Workbook

Sheet الدليل
B1: مكتب الإشراف والتطوير المؤسسي (OID) Oversight and Institutional Development
B2: دليل قالب متابعة الأداء: المنهجية وإرشادات الاستخدام
B4: السلام عليكم ورحمة الله وبركاته، وبعد:
B5: بين أيديكم «قالب متابعة الأداء»، وهو الأداة التي تتابع بها كل مؤسسة مؤشرات أدائها وأنشطتها خلال العام، وتُعِدّ منها تقاريرها الربعية والسنوية، ونقرأ من خلاله أداء مؤسساتنا جميعًا بلغة واحدة. وقد حرصتُ في هذا الدليل على ألا أكتفي بشرح الخانات والمعادلات، بل أن أشرح المنطق الذي بُني عليه الملف؛ فمن فهم لماذا نقيس أحسن كيف يقيس. أرجو أن يُقرأ الدليل كاملًا قبل التعبئة الأولى، وأن يكون المرجع عند كل التباس.
B7: أولًا: مكونات الملف ودورة العمل
B9: يتكون الملف من أوراق مترابطة؛ تُعبَّأ البيانات في كل منها مرة واحدة، وتنتقل تلقائيًا إلى حيث تُحتاج:
B10: الورقة | C10: الغرض | F10: متى تُعبَّأ
B11: KPI Tracking | C11: بطاقة الأداء المتوازن: الأهداف والمؤشرات وأوزانها ومستهدفاتها والمنجز الفعلي لكل فترة، مع حساب نسب الإنجاز والأداء الكلي تلقائيًا. | F11: عند التخطيط، ثم كل ربع
B12: الأنشطة (تقرير تنفيذ الخطة التشغيلية) | C12: سجل موحد للبرامج والأنشطة والفعاليات المجتمعية والتدريب، كل منها في سطر مع ربعه ونوعه، مع إجماليات حسب النوع للفترة المختارة وللسنة. | F12: كل ربع
B13: الملخص | C13: تقرير الأداء: يقرأ نتائج المؤشرات وملخص الخطة التشغيلية تلقائيًا، وتُكتب فيه الإنجازات والتحديات والمقترحات والإحصاءات السنوية. | F13: كل ربع، والإحصاءات السنوية في الربع الرابع
B14: Data | C14: القوائم والإعدادات التي تعتمد عليها المعادلات. | F14: لا تُعبَّأ ولا تُعدَّل
B16: دورة العمل | C16: في بداية العام: تُعتمد الأهداف والمؤشرات ثم المصفوفة كاملة (انظر الخطوة 3 في القسم الرابع)، وتُخطَّط الأنشطة. وفي نهاية كل ربع: يُسجَّل المنجز الفعلي للمؤشرات، وتُضاف أنشطة الربع، وتُكتب إنجازاته وتحدياته، ثم تُختار الفترة في رأس ورقة KPI Tracking ويُرسَل الملف إلى المكتب، فيكون هو تقرير ذلك الربع. وفي الربع الرابع تُعبَّأ الإحصاءات السنوية والمقترحات، فيكون الملف هو التقرير السنوي.
B17: ملف واحد للعام | C17: تعمل المؤسسة على الملف نفسه طوال العام، فيبني كل ربع على ما قبله ولا يُعاد إدخال شيء. ويحتفظ المكتب بنسخة كل ربع كما وصلته.
B19: ثانيًا: لماذا نقيس؟
B21: القياس للتعلّم | C21: لا نقيس لنحاسب، بل لنعرف أين نقف من أهدافنا ونصحّح المسار قبل نهاية العام لا بعده.
B22: ما يُقاس يُدار | C22: وما يُقاس خطأ يُدار خطأ؛ فالمؤشر الرديء أسوأ من غيابه، لأنه يمنح ثقة زائفة ويوجّه الجهد إلى غير موضعه.
B23: لغة مشتركة | C23: مؤسساتنا مختلفة الطبيعة بين إنسانية وتعليمية وتنموية، لكنها تشترك في منهجية واحدة تتيح المقارنة العادلة، وتبادل الخبرات، وتجميع أداء الشبكة كلها.
B24: الصدق قبل الجمال | C24: نسبة إنجاز متواضعة صادقة أنفع للمؤسسة من نسبة عالية لا تعكس الواقع؛ فالأولى تفتح باب التحسين، والثانية تغلقه.
B26: ثالثًا: منطق بطاقة الأداء المتوازن
B28: تنظر البطاقة إلى المؤسسة من أربع زوايا مجتمعة، لأن النظر من زاوية واحدة يُخفي ما يجري في غيرها؛ فقد تتحسن المؤشرات المالية على حساب الموظفين، أو تُنجَز الأنشطة دون أن يصل أثرها إلى المستفيد.
B29: المنظور | C29: السؤال الذي يجيب عنه | D29: محاور التركيز | F29: مثال على مؤشر
B30: أصحاب المصلحة | C30: هل نحقق الأثر المنتظر لمن نخدمهم ولشركائنا والجهات التي نعمل معها؟ | D30: رضا المستفيدين، جودة المخرجات وأثرها، زيادة الوصول، العلاقة مع المانحين والشركاء، السمعة المؤسسية | F30: نسبة رضا المستفيدين عن الخدمات
B31: العمليات الداخلية | C31: في أي عملياتنا يجب أن نتميز لنحقق ذلك الأثر؟ | D31: تنفيذ المشاريع، كفاءة الإجراءات وسرعتها، جودة الخدمة والامتثال | F31: متوسط مدة الاستجابة لطلبات المستفيدين
B32: التعلّم والنمو | C32: ما الذي نحتاجه في أفرادنا وأنظمتنا وثقافتنا لنتطور باستمرار؟ | D32: تطوير الكفاءات والتدريب، الرضا الوظيفي والاستقرار، الحوكمة المؤسسية، التحول الرقمي، الأنظمة والمعرفة المؤسسية، ثقافة التحسين | F32: نسبة تنفيذ خطة التدريب
B33: المالي | C33: كيف نضمن الاستدامة والكفاءة في استخدام الموارد؟ | D33: تنويع الإيرادات والاستدامة، كفاءة الإنفاق، الالتزام بالموازنة | F33: نسبة الإيرادات من مصادر غير المانحين
B34: وللتمييز بين منظوري العمليات الداخلية والتعلّم والنمو: العمليات الداخلية ما يتكرر تنفيذه في كل دورة عمل، أما التعلّم والنمو فقدرات تُبنى وتتراكم وتبقى في المؤسسة.
B36: علاقة السبب والنتيجة | C36: المناظير ليست قوائم منفصلة، بل سلسلة: الاستثمار في التعلّم والنمو يحسّن العمليات، والعمليات الجيدة تحقق الأثر لأصحاب المصلحة، والمنظور المالي يضمن استمرار ذلك كله. وفي مؤسساتنا غير الربحية تأتي رسالتنا تجاه أصحاب المصلحة في رأس السلسلة، ويبقى المال وسيلة للاستدامة لا غاية في ذاته.
B37: معنى التوازن | C37: لذلك خصّصنا لكل منظور 25% من الوزن بالتساوي، حتى لا يطغى منظور على آخر، ولا يُغطّي التفوق في جانب على الإخفاق في جانب.
B39: رابعًا: منهجية المؤشرات خطوة بخطوة
B41: الخطوة 1 الأهداف | C41: ابدؤوا من الأهداف الاستراتيجية المعتمدة في خطة مؤسستكم، لا من المؤشرات المتاحة. ويُصاغ الهدف بصيغة نتيجة مرغوبة («تحسين رضا المستفيدين عن الخدمات»)، لا بصيغة نشاط («تنفيذ استبيان»).
B42: الخطوة 2 المؤشر | C42: المؤشر الجيد يقيس الهدف مباشرة، وتتوفر له بيانات موثوقة، ويكون تعريفه محددًا بحيث لو حسبه شخصان لوصلا إلى الرقم نفسه. ويكفي من مؤشرين إلى أربعة لكل هدف؛ فكثرة المؤشرات تشتّت ولا تضيف.
B43: الخطوة 3 الاعتماد المرحلي | C43: يعتمد المكتب المصفوفة على مرحلتين: الأولى للأهداف والمؤشرات قبل أي تعبئة، ويتحقق فيها من انتماء كل هدف إلى منظوره ومن صلاحية مؤشراته؛ والثانية للمصفوفة كاملة بأوزانها ومستهدفاتها قبل بدء القياس. فلا تبدؤوا التعبئة قبل اعتماد المرحلة الأولى، ولا الرصد قبل اعتماد الثانية؛ لأن نقل هدف إلى منظور آخر أو تغيير مؤشر بعد التعبئة يعني إعادة العمل كله.
B44: الخطوة 4 القياس والوحدة | C44: حددوا طبيعة القياس أولًا: كمي نسبي ووحدته النسبة %، أو كمي عددي ووحداته العدد أو المبلغ أو الأيام، أو نوعي ويُحوَّل إلى درجة على مقياس ليكرت الخماسي ليصبح قابلًا للقياس والمقارنة.
B45: الخطوة 5 دور المؤشر | C45: المؤشر القيادي يقيس ما نفعله الآن ويقود إلى النتيجة (مثل ساعات التدريب)، ومؤشر النتائج يقيس ما تحقق (مثل رضا المستفيدين). احرصوا أن يجمع كل هدف بين النوعين ما أمكن: فإذا تأخرت النتيجة رجعنا إلى المؤشرات القيادية؛ فإن تأخرت هي أيضًا فالخلل في التنفيذ.
B46: الخطوة 6 القطبية | C46: تصاعدي: كلما زاد الرقم كان أفضل (عدد المستفيدين). تنازلي: كلما قلّ كان أفضل (مدة الاستجابة، نسبة التسرب).
B47: الخطوة 7 طريقة الاحتساب | C47: هذا أهم قرار في تعبئة المؤشر، وهو وحده الذي يحدد كيف يُحسب المنجز السنوي، أيًّا كانت الوحدة. وقبل الاختيار اسألوا: هل الرقم الذي سأسجله في هذه الفترة جزءٌ جديد يُضاف إلى ما قبله؟ أم رصيدٌ حتى تاريخه؟ أم قياسٌ لمستوى قائم؟
B48: طريقة الاحتساب | C48: ماذا يُسجَّل في كل فترة | D48: كيف يُحسب المنجز السنوي | E48: أمثلة
B49: مستقل | C49: ما أُنجز داخل الفترة فقط | D49: مجموع الفترات | E49: عدد المستفيدين الجدد، الإيرادات المحصلة، نسبة إنجاز مقسّمة على الفترات
B50: تراكمي | C50: الرصيد المتحقق حتى نهاية الفترة | D50: آخر قيمة مسجلة | E50: نسبة إنجاز المشروع حتى تاريخه، عدد الشراكات الفعالة
B51: متوسط | C51: قياس مستقل لمستوى قائم | D51: متوسط الفترات | E51: نسبة رضا المستفيدين، نسبة الحضور، درجات ليكرت
...

Sheet Guide
B1: Oversight and Institutional Development (OID) مكتب الإشراف والتطوير المؤسسي
B2: Performance Monitoring Template Guide: Methodology and Instructions
B4: Dear colleagues,
B5: Before you is the Performance Monitoring Template: the tool with which each institution tracks its key performance indicators and activities throughout the year and prepares its quarterly and annual reports, and through which we read the performance of all our institutions in one common language. In this guide I have not limited myself to explaining the fields and formulas; I have also set out the reasoning on which the file is built, because whoever understands why we measure measures better. Please read the guide in full before the first use, and return to it whenever something is unclear.
B7: First: The File and the Work Cycle
B9: The file consists of linked sheets; data is entered once in each and flows automatically to wherever it is needed:
B10: Sheet | C10: Purpose | F10: When it is filled in
B11: KPI Tracking | C11: The balanced scorecard: objectives, indicators, weights, targets and actual achievement for each period, with achievement rates and overall performance calculated automatically. | F11: At planning, then every quarter
B12: Activities (الأنشطة) Operational Plan Implementation Report | C12: A single register of programs, activities, community events and training, each in a row with its quarter and type, with totals by type for the selected period and for the year. | F12: Every quarter
B13: Summary (الملخص) | C13: The performance report: it reads the indicator results and the operational plan summary automatically, and is where achievements, challenges, proposals and annual statistics are written. | F13: Every quarter; annual statistics in the fourth quarter
B14: Data | C14: The lists and settings the formulas rely on. | F14: Neither filled in nor changed
B16: The work cycle | C16: At the start of the year, the objectives and indicators, then the full matrix, are approved (see Step 3 in Section Four), and activities are planned. At the end of each quarter, record the actual achievement of the indicators, add the quarter’s activities, and write up its achievements and challenges; then select the period at the top of the KPI Tracking sheet and send the file to the Office. That is the report for the quarter. In the fourth quarter, fill in the annual statistics and proposals, and the file becomes the annual report.
B17: One file per year | C17: The institution works on the same file throughout the year, so each quarter builds on the previous one and nothing is entered twice. The Office keeps a copy of each quarterly submission as received.
B19: Second: Why Do We Measure?
B21: Measuring to learn | C21: We do not measure to hold people to account, but to know where we stand against our objectives and to correct course before the end of the year, not after it.
B22: What gets measured gets managed | C22: And what is measured wrongly is managed wrongly: a poor indicator is worse than none, because it gives false confidence and directs effort to the wrong place.
B23: A common language | C23: Our institutions differ in nature (humanitarian, educational and developmental), but they share one methodology that allows fair comparison, the exchange of experience, and the consolidation of the whole network’s performance.
B24: Honesty before appearance | C24: A modest but honest achievement rate is more useful to the institution than a high rate that does not reflect reality: the first opens the door to improvement; the second closes it.
B26: Third: The Logic of the Balanced Scorecard
B28: The scorecard looks at the institution from four angles together, because looking from one angle hides what happens in the others: financial indicators may improve at the expense of staff, or activities may be completed without their impact reaching the beneficiary.
B29: Perspective | C29: The question it answers | D29: Focus areas | F29: Example indicator
B30: Stakeholders | C30: Are we delivering the expected impact for those we serve, our partners and the bodies we work with? | D30: Beneficiary satisfaction, quality and impact of outputs, expanding reach, relations with donors and partners, institutional reputation | F30: Beneficiary satisfaction rate with services
B31: Internal Processes | C31: Which of our processes must we excel at to achieve that impact? | D31: Project implementation, efficiency and speed of procedures, service quality and compliance | F31: Average response time to beneficiary requests
B32: Learning & Growth | C32: What do we need in our people, systems and culture to keep developing? | D32: Staff competencies and training, job satisfaction and retention, institutional governance, digital transformation, institutional systems and knowledge, a culture of improvement | F32: Training plan implementation rate
B33: Financial | C33: How do we ensure sustainability and the efficient use of resources? | D33: Revenue diversification and sustainability, spending efficiency, budget adherence | F33: Share of revenue from non-donor sources
B34: To tell Internal Processes from Learning & Growth: internal processes are what is carried out again in every work cycle, while learning and growth are capabilities that are built up, accumulate and remain within the institution.
B36: Cause and effect | C36: The perspectives are not separate lists but a chain: investing in learning and growth improves processes, good processes deliver impact for stakeholders, and the financial perspective sustains it all. In our non-profit institutions, our mission towards stakeholders sits at the top of the chain, and money remains a means of sustainability, not an end in itself.
B37: The meaning of balance | C37: That is why each perspective carries an equal 25% of the weight, so that no perspective dominates another and excellence in one area does not mask failure in another.
B39: Fourth: The Indicator Methodology Step by Step
B41: Step 1 Objectives | C41: Start from the strategic objectives approved in your institution’s plan, not from the indicators that happen to be available. Phrase each objective as a desired result (“Improve beneficiary satisfaction with services”), not as an activity (“Conduct a survey”).
B42: Step 2 The indicator | C42: A good indicator measures the objective directly, is supported by reliable data, and is defined precisely enough that two people calculating it would arrive at the same number. Two to four indicators per objective are enough; too many indicators scatter attention and add nothing.
B43: Step 3 Phased approval | C43: The Office approves the matrix in two stages. The first covers the objectives and indicators, before anything is filled in: the Office checks that each objective belongs to its perspective and that its indicators are sound. The second covers the full matrix, with its weights and targets, before measurement begins. Do not start filling in before the first stage is approved, nor start monitoring before the second, because moving an objective to another perspective or changing an indicator after filling means redoing the whole work.
B44: Step 4 Measurement & unit | C44: First set the measurement type: quantitative percentage, with % as its unit; quantitative number, with count, amount or days as its unit; or qualitative, converted to a score on the five-point Likert scale so that it can be measured and compared.
B45: Step 5 KPI role | C45: A leading indicator measures what we are doing now that leads to the result (e.g. training hours); a lagging indicator measures what has been achieved (e.g. beneficiary satisfaction). Wherever possible, give each objective both types: if the result falls behind, we look back at the leading indicators, and if they are behind too, the problem lies in execution.
B46: Step 6 Polarity | C46: Ascending: the higher the number, the better (number of beneficiaries). Descending: the lower the number, the better (response time, dropout rate).
B47: Step 7 Calculation method | C47: This is the most important decision when filling in an indicator, and it alone determines how the annual achievement is calculated, whatever the unit. Before choosing, ask: is the number I record for this period a new portion added to what came before? A running balance to date? Or a measurement of an existing level?
B48: Calculation method | C48: What is recorded each period | D48: How the annual achievement is calculated | E48: Examples
B49: Independent | C49: Only what was achieved within the period | D49: Sum of the periods | E49: New beneficiaries, revenue collected, an achievement rate split across periods
B50: Cumulative | C50: The balance achieved by the end of the period | D50: Last recorded value | E50: Project completion rate to date, number of active partnerships
B51: Average | C51: A separate measurement of an existing level | D51: Average of the periods | E51: Beneficiary satisfaction rate, attendance rate, Likert scores
...

Sheet KPI Tracking
A1: مكتب الإشراف والتطوير المؤسسي (OID) Oversight and Institutional Development
A2: متابعة مؤشرات الأداء / KPI Tracking
B3: معدّ التقرير Report Prepared By | C3: معدّ تجريبي | E3: اسم المؤسسة Institution | F3: مؤسسة زمزم Zamzam Foundation | J3: مراجعة واعتماد Review & Approval | O3: الفترة Period | P3: Q2
B4: منظور أصحاب المصلحة Stakeholder Perspective | E4: العوامل الأساسية / Key Drivers | M4: الإجمالي Total | N4: المخطط والمنجز / Planned & Achieved | V4: النتائج / Results
A5: # | B5: الهدف Objective | C5: مؤشر الأداء KPI | D5: الكود Code | E5: القياس Measurement | F5: دور المؤشر KPI Role | G5: الوحدة Unit | H5: القطبية Polarity | I5: التردد Frequency | J5: الوزن Weight % | K5: خط الأساس Baseline | L5: المستهدف السنوي Annual Target | M5: الإجمالي Total (B+T) | N5: مخطط Q1 Plan | O5: منجز Q1 Actual | P5: مخطط Q2 Plan | Q5: منجز Q2 Actual | R5: مخطط Q3 Plan | S5: منجز Q3 Actual | T5: مخطط Q4 Plan | U5: منجز Q4 Actual | V5: المنجز السنوي Annual Achieved | W5: نسبة الإنجاز Achievement % | X5: النسبة المرجحة Weighted %
A6: =IF(B6="","",COUNTA(B$5:B6)-1) -> 1 | B6: تحسين رضا المستفيدين عن الخدمات | C6: نسبة رضا المستفيدين | D6: =IFERROR(VLOOKUP($F$3,Data!$A:$B,2,0)&"-S"&TEXT(ROW()-ROW($D$5),"0"),"-S"&TEXT(ROW()-ROW($D$5),"0")) -> ZF-S1 | E6: كمي نسبي Quantitative % | F6: نتائج Lagging | G6: نسبة % Percentage | H6: تصاعدي Ascending | I6: ربعي - متوسط Quarterly-Average | J6: 10 | K6: 70 | L6: 80 | M6: =IFERROR(IF(OR(K6="",L6="",ISNUMBER(SEARCH("متوسط",I6)),ISNUMBER(SEARCH("ليكرت",G6)),ISNUMBER(SEARCH("نوعي",E6))),"",K6+L6),"") | N6: 80 | O6: 78 | P6: 80 | Q6: 80 | R6: 80 | T6: 80 | V6: =IFERROR(IF(COUNT(O6,Q6,S6,U6)=0,"",IF(ISNUMBER(SEARCH("تراكمي",I6)),IF(ISNUMBER(U6),U6,IF(ISNUMBER(S6),S6,IF(ISNUMBER(Q6),Q6,O6))),IF(ISNUMBER(SEARCH("متوسط",I6)),AVERAGE(O6,Q6,S6,U6),IF(AND(ISNUMBER(SEARCH("سنوي",I6)),ISERROR(SEARCH("نصف",I6))),IF(ISNUMBER(U6),U6,""),SUM(O6,Q6,S6,U6))))),"-") -> 79 | W6: =IF(OR(NOT(ISNUMBER(L6)),NOT(ISNUMBER(V6))),"",IFERROR(IF(ISNUMBER(SEARCH("تنازلي",H6)), IF(V6=0,100,(L6/V6)*100), (V6/L6)*100),"-")) -> 98.75 | X6: =IF(AND(ISNUMBER(W6),ISNUMBER(J6)),MIN(W6,100)/100*J6,"") -> 9.875
A7: =IF(B7="","",COUNTA(B$5:B7)-1) | C7: عدد المستفيدين الجدد | D7: =IFERROR(VLOOKUP($F$3,Data!$A:$B,2,0)&"-S"&TEXT(ROW()-ROW($D$5),"0"),"-S"&TEXT(ROW()-ROW($D$5),"0")) -> ZF-S2 | E7: كمي عددي Quantitative Number | F7: نتائج Lagging | G7: عدد Number | H7: تصاعدي Ascending | I7: ربعي - مستقل Quarterly-Independent | J7: 10 | K7: 1000 | L7: 2000 | M7: =IFERROR(IF(OR(K7="",L7="",ISNUMBER(SEARCH("متوسط",I7)),ISNUMBER(SEARCH("ليكرت",G7)),ISNUMBER(SEARCH("نوعي",E7))),"",K7+L7),"") -> 3000 | N7: 400 | O7: 380 | P7: 600 | Q7: 700 | R7: 500 | T7: 500 | V7: =IFERROR(IF(COUNT(O7,Q7,S7,U7)=0,"",IF(ISNUMBER(SEARCH("تراكمي",I7)),IF(ISNUMBER(U7),U7,IF(ISNUMBER(S7),S7,IF(ISNUMBER(Q7),Q7,O7))),IF(ISNUMBER(SEARCH("متوسط",I7)),AVERAGE(O7,Q7,S7,U7),IF(AND(ISNUMBER(SEARCH("سنوي",I7)),ISERROR(SEARCH("نصف",I7))),IF(ISNUMBER(U7),U7,""),SUM(O7,Q7,S7,U7))))),"-") -> 1080 | W7: =IF(OR(NOT(ISNUMBER(L7)),NOT(ISNUMBER(V7))),"",IFERROR(IF(ISNUMBER(SEARCH("تنازلي",H7)), IF(V7=0,100,(L7/V7)*100), (V7/L7)*100),"-")) -> 54 | X7: =IF(AND(ISNUMBER(W7),ISNUMBER(J7)),MIN(W7,100)/100*J7,"") -> 5.4
A8: =IF(B8="","",COUNTA(B$5:B8)-1) -> 2 | B8: تعزيز الشراكات | C8: عدد الشراكات الفعالة | D8: =IFERROR(VLOOKUP($F$3,Data!$A:$B,2,0)&"-S"&TEXT(ROW()-ROW($D$5),"0"),"-S"&TEXT(ROW()-ROW($D$5),"0")) -> ZF-S3 | E8: كمي عددي Quantitative Number | F8: قيادي Leading | G8: عدد Number | H8: تصاعدي Ascending | I8: ربعي - تراكمي Quarterly-Cumulative | J8: 5 | K8: 3 | L8: 8 | M8: =IFERROR(IF(OR(K8="",L8="",ISNUMBER(SEARCH("متوسط",I8)),ISNUMBER(SEARCH("ليكرت",G8)),ISNUMBER(SEARCH("نوعي",E8))),"",K8+L8),"") -> 11 | N8: 4 | O8: 4 | P8: 5 | Q8: 6 | R8: 6 | T8: 8 | V8: =IFERROR(IF(COUNT(O8,Q8,S8,U8)=0,"",IF(ISNUMBER(SEARCH("تراكمي",I8)),IF(ISNUMBER(U8),U8,IF(ISNUMBER(S8),S8,IF(ISNUMBER(Q8),Q8,O8))),IF(ISNUMBER(SEARCH("متوسط",I8)),AVERAGE(O8,Q8,S8,U8),IF(AND(ISNUMBER(SEARCH("سنوي",I8)),ISERROR(SEARCH("نصف",I8))),IF(ISNUMBER(U8),U8,""),SUM(O8,Q8,S8,U8))))),"-") -> 6 | W8: =IF(OR(NOT(ISNUMBER(L8)),NOT(ISNUMBER(V8))),"",IFERROR(IF(ISNUMBER(SEARCH("تنازلي",H8)), IF(V8=0,100,(L8/V8)*100), (V8/L8)*100),"-")) -> 75 | X8: =IF(AND(ISNUMBER(W8),ISNUMBER(J8)),MIN(W8,100)/100*J8,"") -> 3.75
A9: =IF(B9="","",COUNTA(B$5:B9)-1) | D9: =IFERROR(VLOOKUP($F$3,Data!$A:$B,2,0)&"-S"&TEXT(ROW()-ROW($D$5),"0"),"-S"&TEXT(ROW()-ROW($D$5),"0")) -> ZF-S4 | M9: =IFERROR(IF(OR(K9="",L9="",ISNUMBER(SEARCH("متوسط",I9)),ISNUMBER(SEARCH("ليكرت",G9)),ISNUMBER(SEARCH("نوعي",E9))),"",K9+L9),"") | V9: =IFERROR(IF(COUNT(O9,Q9,S9,U9)=0,"",IF(ISNUMBER(SEARCH("تراكمي",I9)),IF(ISNUMBER(U9),U9,IF(ISNUMBER(S9),S9,IF(ISNUMBER(Q9),Q9,O9))),IF(ISNUMBER(SEARCH("متوسط",I9)),AVERAGE(O9,Q9,S9,U9),IF(AND(ISNUMBER(SEARCH("سنوي",I9)),ISERROR(SEARCH("نصف",I9))),IF(ISNUMBER(U9),U9,""),SUM(O9,Q9,S9,U9))))),"-") | W9: =IF(OR(NOT(ISNUMBER(L9)),NOT(ISNUMBER(V9))),"",IFERROR(IF(ISNUMBER(SEARCH("تنازلي",H9)), IF(V9=0,100,(L9/V9)*100), (V9/L9)*100),"-")) | X9: =IF(AND(ISNUMBER(W9),ISNUMBER(J9)),MIN(W9,100)/100*J9,"")
A10: =IF(B10="","",COUNTA(B$5:B10)-1) | D10: =IFERROR(VLOOKUP($F$3,Data!$A:$B,2,0)&"-S"&TEXT(ROW()-ROW($D$5),"0"),"-S"&TEXT(ROW()-ROW($D$5),"0")) -> ZF-S5 | M10: =IFERROR(IF(OR(K10="",L10="",ISNUMBER(SEARCH("متوسط",I10)),ISNUMBER(SEARCH("ليكرت",G10)),ISNUMBER(SEARCH("نوعي",E10))),"",K10+L10),"") | V10: =IFERROR(IF(COUNT(O10,Q10,S10,U10)=0,"",IF(ISNUMBER(SEARCH("تراكمي",I10)),IF(ISNUMBER(U10),U10,IF(ISNUMBER(S10),S10,IF(ISNUMBER(Q10),Q10,O10))),IF(ISNUMBER(SEARCH("متوسط",I10)),AVERAGE(O10,Q10,S10,U10),IF(AND(ISNUMBER(SEARCH("سنوي",I10)),ISERROR(SEARCH("نصف",I10))),IF(ISNUMBER(U10),U10,""),SUM(O10,Q10,S10,U10))))),"-") | W10: =IF(OR(NOT(ISNUMBER(L10)),NOT(ISNUMBER(V10))),"",IFERROR(IF(ISNUMBER(SEARCH("تنازلي",H10)), IF(V10=0,100,(L10/V10)*100), (V10/L10)*100),"-")) | X10: =IF(AND(ISNUMBER(W10),ISNUMBER(J10)),MIN(W10,100)/100*J10,"")
A11: =IF(B11="","",COUNTA(B$5:B11)-1) | D11: =IFERROR(VLOOKUP($F$3,Data!$A:$B,2,0)&"-S"&TEXT(ROW()-ROW($D$5),"0"),"-S"&TEXT(ROW()-ROW($D$5),"0")) -> ZF-S6 | M11: =IFERROR(IF(OR(K11="",L11="",ISNUMBER(SEARCH("متوسط",I11)),ISNUMBER(SEARCH("ليكرت",G11)),ISNUMBER(SEARCH("نوعي",E11))),"",K11+L11),"") | V11: =IFERROR(IF(COUNT(O11,Q11,S11,U11)=0,"",IF(ISNUMBER(SEARCH("تراكمي",I11)),IF(ISNUMBER(U11),U11,IF(ISNUMBER(S11),S11,IF(ISNUMBER(Q11),Q11,O11))),IF(ISNUMBER(SEARCH("متوسط",I11)),AVERAGE(O11,Q11,S11,U11),IF(AND(ISNUMBER(SEARCH("سنوي",I11)),ISERROR(SEARCH("نصف",I11))),IF(ISNUMBER(U11),U11,""),SUM(O11,Q11,S11,U11))))),"-") | W11: =IF(OR(NOT(ISNUMBER(L11)),NOT(ISNUMBER(V11))),"",IFERROR(IF(ISNUMBER(SEARCH("تنازلي",H11)), IF(V11=0,100,(L11/V11)*100), (V11/L11)*100),"-")) | X11: =IF(AND(ISNUMBER(W11),ISNUMBER(J11)),MIN(W11,100)/100*J11,"")
A12: =IF(B12="","",COUNTA(B$5:B12)-1) | D12: =IFERROR(VLOOKUP($F$3,Data!$A:$B,2,0)&"-S"&TEXT(ROW()-ROW($D$5),"0"),"-S"&TEXT(ROW()-ROW($D$5),"0")) -> ZF-S7 | M12: =IFERROR(IF(OR(K12="",L12="",ISNUMBER(SEARCH("متوسط",I12)),ISNUMBER(SEARCH("ليكرت",G12)),ISNUMBER(SEARCH("نوعي",E12))),"",K12+L12),"") | V12: =IFERROR(IF(COUNT(O12,Q12,S12,U12)=0,"",IF(ISNUMBER(SEARCH("تراكمي",I12)),IF(ISNUMBER(U12),U12,IF(ISNUMBER(S12),S12,IF(ISNUMBER(Q12),Q12,O12))),IF(ISNUMBER(SEARCH("متوسط",I12)),AVERAGE(O12,Q12,S12,U12),IF(AND(ISNUMBER(SEARCH("سنوي",I12)),ISERROR(SEARCH("نصف",I12))),IF(ISNUMBER(U12),U12,""),SUM(O12,Q12,S12,U12))))),"-") | W12: =IF(OR(NOT(ISNUMBER(L12)),NOT(ISNUMBER(V12))),"",IFERROR(IF(ISNUMBER(SEARCH("تنازلي",H12)), IF(V12=0,100,(L12/V12)*100), (V12/L12)*100),"-")) | X12: =IF(AND(ISNUMBER(W12),ISNUMBER(J12)),MIN(W12,100)/100*J12,"")
A13: =IF(B13="","",COUNTA(B$5:B13)-1) | D13: =IFERROR(VLOOKUP($F$3,Data!$A:$B,2,0)&"-S"&TEXT(ROW()-ROW($D$5),"0"),"-S"&TEXT(ROW()-ROW($D$5),"0")) -> ZF-S8 | M13: =IFERROR(IF(OR(K13="",L13="",ISNUMBER(SEARCH("متوسط",I13)),ISNUMBER(SEARCH("ليكرت",G13)),ISNUMBER(SEARCH("نوعي",E13))),"",K13+L13),"") | V13: =IFERROR(IF(COUNT(O13,Q13,S13,U13)=0,"",IF(ISNUMBER(SEARCH("تراكمي",I13)),IF(ISNUMBER(U13),U13,IF(ISNUMBER(S13),S13,IF(ISNUMBER(Q13),Q13,O13))),IF(ISNUMBER(SEARCH("متوسط",I13)),AVERAGE(O13,Q13,S13,U13),IF(AND(ISNUMBER(SEARCH("سنوي",I13)),ISERROR(SEARCH("نصف",I13))),IF(ISNUMBER(U13),U13,""),SUM(O13,Q13,S13,U13))))),"-") | W13: =IF(OR(NOT(ISNUMBER(L13)),NOT(ISNUMBER(V13))),"",IFERROR(IF(ISNUMBER(SEARCH("تنازلي",H13)), IF(V13=0,100,(L13/V13)*100), (V13/L13)*100),"-")) | X13: =IF(AND(ISNUMBER(W13),ISNUMBER(J13)),MIN(W13,100)/100*J13,"")
A14: =IF(B14="","",COUNTA(B$5:B14)-1) | D14: =IFERROR(VLOOKUP($F$3,Data!$A:$B,2,0)&"-S"&TEXT(ROW()-ROW($D$5),"0"),"-S"&TEXT(ROW()-ROW($D$5),"0")) -> ZF-S9 | M14: =IFERROR(IF(OR(K14="",L14="",ISNUMBER(SEARCH("متوسط",I14)),ISNUMBER(SEARCH("ليكرت",G14)),ISNUMBER(SEARCH("نوعي",E14))),"",K14+L14),"") | V14: =IFERROR(IF(COUNT(O14,Q14,S14,U14)=0,"",IF(ISNUMBER(SEARCH("تراكمي",I14)),IF(ISNUMBER(U14),U14,IF(ISNUMBER(S14),S14,IF(ISNUMBER(Q14),Q14,O14))),IF(ISNUMBER(SEARCH("متوسط",I14)),AVERAGE(O14,Q14,S14,U14),IF(AND(ISNUMBER(SEARCH("سنوي",I14)),ISERROR(SEARCH("نصف",I14))),IF(ISNUMBER(U14),U14,""),SUM(O14,Q14,S14,U14))))),"-") | W14: =IF(OR(NOT(ISNUMBER(L14)),NOT(ISNUMBER(V14))),"",IFERROR(IF(ISNUMBER(SEARCH("تنازلي",H14)), IF(V14=0,100,(L14/V14)*100), (V14/L14)*100),"-")) | X14: =IF(AND(ISNUMBER(W14),ISNUMBER(J14)),MIN(W14,100)/100*J14,"")
A15: =IF(B15="","",COUNTA(B$5:B15)-1) | D15: =IFERROR(VLOOKUP($F$3,Data!$A:$B,2,0)&"-S"&TEXT(ROW()-ROW($D$5),"0"),"-S"&TEXT(ROW()-ROW($D$5),"0")) -> ZF-S10 | M15: =IFERROR(IF(OR(K15="",L15="",ISNUMBER(SEARCH("متوسط",I15)),ISNUMBER(SEARCH("ليكرت",G15)),ISNUMBER(SEARCH("نوعي",E15))),"",K15+L15),"") | V15: =IFERROR(IF(COUNT(O15,Q15,S15,U15)=0,"",IF(ISNUMBER(SEARCH("تراكمي",I15)),IF(ISNUMBER(U15),U15,IF(ISNUMBER(S15),S15,IF(ISNUMBER(Q15),Q15,O15))),IF(ISNUMBER(SEARCH("متوسط",I15)),AVERAGE(O15,Q15,S15,U15),IF(AND(ISNUMBER(SEARCH("سنوي",I15)),ISERROR(SEARCH("نصف",I15))),IF(ISNUMBER(U15),U15,""),SUM(O15,Q15,S15,U15))))),"-") | W15: =IF(OR(NOT(ISNUMBER(L15)),NOT(ISNUMBER(V15))),"",IFERROR(IF(ISNUMBER(SEARCH("تنازلي",H15)), IF(V15=0,100,(L15/V15)*100), (V15/L15)*100),"-")) | X15: =IF(AND(ISNUMBER(W15),ISNUMBER(J15)),MIN(W15,100)/100*J15,"")
A16: =IF(B16="","",COUNTA(B$5:B16)-1) | D16: =IFERROR(VLOOKUP($F$3,Data!$A:$B,2,0)&"-S"&TEXT(ROW()-ROW($D$5),"0"),"-S"&TEXT(ROW()-ROW($D$5),"0")) -> ZF-S11 | M16: =IFERROR(IF(OR(K16="",L16="",ISNUMBER(SEARCH("متوسط",I16)),ISNUMBER(SEARCH("ليكرت",G16)),ISNUMBER(SEARCH("نوعي",E16))),"",K16+L16),"") | V16: =IFERROR(IF(COUNT(O16,Q16,S16,U16)=0,"",IF(ISNUMBER(SEARCH("تراكمي",I16)),IF(ISNUMBER(U16),U16,IF(ISNUMBER(S16),S16,IF(ISNUMBER(Q16),Q16,O16))),IF(ISNUMBER(SEARCH("متوسط",I16)),AVERAGE(O16,Q16,S16,U16),IF(AND(ISNUMBER(SEARCH("سنوي",I16)),ISERROR(SEARCH("نصف",I16))),IF(ISNUMBER(U16),U16,""),SUM(O16,Q16,S16,U16))))),"-") | W16: =IF(OR(NOT(ISNUMBER(L16)),NOT(ISNUMBER(V16))),"",IFERROR(IF(ISNUMBER(SEARCH("تنازلي",H16)), IF(V16=0,100,(L16/V16)*100), (V16/L16)*100),"-")) | X16: =IF(AND(ISNUMBER(W16),ISNUMBER(J16)),MIN(W16,100)/100*J16,"")
A17: =IF(B17="","",COUNTA(B$5:B17)-1) | D17: =IFERROR(VLOOKUP($F$3,Data!$A:$B,2,0)&"-S"&TEXT(ROW()-ROW($D$5),"0"),"-S"&TEXT(ROW()-ROW($D$5),"0")) -> ZF-S12 | M17: =IFERROR(IF(OR(K17="",L17="",ISNUMBER(SEARCH("متوسط",I17)),ISNUMBER(SEARCH("ليكرت",G17)),ISNUMBER(SEARCH("نوعي",E17))),"",K17+L17),"") | V17: =IFERROR(IF(COUNT(O17,Q17,S17,U17)=0,"",IF(ISNUMBER(SEARCH("تراكمي",I17)),IF(ISNUMBER(U17),U17,IF(ISNUMBER(S17),S17,IF(ISNUMBER(Q17),Q17,O17))),IF(ISNUMBER(SEARCH("متوسط",I17)),AVERAGE(O17,Q17,S17,U17),IF(AND(ISNUMBER(SEARCH("سنوي",I17)),ISERROR(SEARCH("نصف",I17))),IF(ISNUMBER(U17),U17,""),SUM(O17,Q17,S17,U17))))),"-") | W17: =IF(OR(NOT(ISNUMBER(L17)),NOT(ISNUMBER(V17))),"",IFERROR(IF(ISNUMBER(SEARCH("تنازلي",H17)), IF(V17=0,100,(L17/V17)*100), (V17/L17)*100),"-")) | X17: =IF(AND(ISNUMBER(W17),ISNUMBER(J17)),MIN(W17,100)/100*J17,"")
A18: =IF(B18="","",COUNTA(B$5:B18)-1) | D18: =IFERROR(VLOOKUP($F$3,Data!$A:$B,2,0)&"-S"&TEXT(ROW()-ROW($D$5),"0"),"-S"&TEXT(ROW()-ROW($D$5),"0")) -> ZF-S13 | M18: =IFERROR(IF(OR(K18="",L18="",ISNUMBER(SEARCH("متوسط",I18)),ISNUMBER(SEARCH("ليكرت",G18)),ISNUMBER(SEARCH("نوعي",E18))),"",K18+L18),"") | V18: =IFERROR(IF(COUNT(O18,Q18,S18,U18)=0,"",IF(ISNUMBER(SEARCH("تراكمي",I18)),IF(ISNUMBER(U18),U18,IF(ISNUMBER(S18),S18,IF(ISNUMBER(Q18),Q18,O18))),IF(ISNUMBER(SEARCH("متوسط",I18)),AVERAGE(O18,Q18,S18,U18),IF(AND(ISNUMBER(SEARCH("سنوي",I18)),ISERROR(SEARCH("نصف",I18))),IF(ISNUMBER(U18),U18,""),SUM(O18,Q18,S18,U18))))),"-") | W18: =IF(OR(NOT(ISNUMBER(L18)),NOT(ISNUMBER(V18))),"",IFERROR(IF(ISNUMBER(SEARCH("تنازلي",H18)), IF(V18=0,100,(L18/V18)*100), (V18/L18)*100),"-")) | X18: =IF(AND(ISNUMBER(W18),ISNUMBER(J18)),MIN(W18,100)/100*J18,"")
A19: =IF(B19="","",COUNTA(B$5:B19)-1) | D19: =IFERROR(VLOOKUP($F$3,Data!$A:$B,2,0)&"-S"&TEXT(ROW()-ROW($D$5),"0"),"-S"&TEXT(ROW()-ROW($D$5),"0")) -> ZF-S14 | M19: =IFERROR(IF(OR(K19="",L19="",ISNUMBER(SEARCH("متوسط",I19)),ISNUMBER(SEARCH("ليكرت",G19)),ISNUMBER(SEARCH("نوعي",E19))),"",K19+L19),"") | V19: =IFERROR(IF(COUNT(O19,Q19,S19,U19)=0,"",IF(ISNUMBER(SEARCH("تراكمي",I19)),IF(ISNUMBER(U19),U19,IF(ISNUMBER(S19),S19,IF(ISNUMBER(Q19),Q19,O19))),IF(ISNUMBER(SEARCH("متوسط",I19)),AVERAGE(O19,Q19,S19,U19),IF(AND(ISNUMBER(SEARCH("سنوي",I19)),ISERROR(SEARCH("نصف",I19))),IF(ISNUMBER(U19),U19,""),SUM(O19,Q19,S19,U19))))),"-") | W19: =IF(OR(NOT(ISNUMBER(L19)),NOT(ISNUMBER(V19))),"",IFERROR(IF(ISNUMBER(SEARCH("تنازلي",H19)), IF(V19=0,100,(L19/V19)*100), (V19/L19)*100),"-")) | X19: =IF(AND(ISNUMBER(W19),ISNUMBER(J19)),MIN(W19,100)/100*J19,"")
A20: =IF(B20="","",COUNTA(B$5:B20)-1) | D20: =IFERROR(VLOOKUP($F$3,Data!$A:$B,2,0)&"-S"&TEXT(ROW()-ROW($D$5),"0"),"-S"&TEXT(ROW()-ROW($D$5),"0")) -> ZF-S15 | M20: =IFERROR(IF(OR(K20="",L20="",ISNUMBER(SEARCH("متوسط",I20)),ISNUMBER(SEARCH("ليكرت",G20)),ISNUMBER(SEARCH("نوعي",E20))),"",K20+L20),"") | V20: =IFERROR(IF(COUNT(O20,Q20,S20,U20)=0,"",IF(ISNUMBER(SEARCH("تراكمي",I20)),IF(ISNUMBER(U20),U20,IF(ISNUMBER(S20),S20,IF(ISNUMBER(Q20),Q20,O20))),IF(ISNUMBER(SEARCH("متوسط",I20)),AVERAGE(O20,Q20,S20,U20),IF(AND(ISNUMBER(SEARCH("سنوي",I20)),ISERROR(SEARCH("نصف",I20))),IF(ISNUMBER(U20),U20,""),SUM(O20,Q20,S20,U20))))),"-") | W20: =IF(OR(NOT(ISNUMBER(L20)),NOT(ISNUMBER(V20))),"",IFERROR(IF(ISNUMBER(SEARCH("تنازلي",H20)), IF(V20=0,100,(L20/V20)*100), (V20/L20)*100),"-")) | X20: =IF(AND(ISNUMBER(W20),ISNUMBER(J20)),MIN(W20,100)/100*J20,"")
... A35: =IF(B35="","",COUNTA(B$5:B35)-1) | D35: =IFERROR(VLOOKUP($F$3,Data!$A:$B,2,0)&"-S"&TEXT(ROW()-ROW($D$5),"0"),"-S"&TEXT(ROW()-ROW($D$5),"0")) -> ZF-S30 | M35: =IFERROR(IF(OR(K35="",L35="",ISNUMBER(SEARCH("متوسط",I35)),ISNUMBER(SEARCH("ليكرت",G35)),ISNUMBER(SEARCH("نوعي",E35))),"",K35+L35),"") | V35: =IFERROR(IF(COUNT(O35,Q35,S35,U35)=0,"",IF(ISNUMBER(SEARCH("تراكمي",I35)),IF(ISNUMBER(U35),U35,IF(ISNUMBER(S35),S35,IF(ISNUMBER(Q35),Q35,O35))),IF(ISNUMBER(SEARCH("متوسط",I35)),AVERAGE(O35,Q35,S35,U35),IF(AND(ISNUMBER(SEARCH("سنوي",I35)),ISERROR(SEARCH("نصف",I35))),IF(ISNUMBER(U35),U35,""),SUM(O35,Q35,S35,U35))))),"-") | W35: =IF(OR(NOT(ISNUMBER(L35)),NOT(ISNUMBER(V35))),"",IFERROR(IF(ISNUMBER(SEARCH("تنازلي",H35)), IF(V35=0,100,(L35/V35)*100), (V35/L35)*100),"-")) | X35: =IF(AND(ISNUMBER(W35),ISNUMBER(J35)),MIN(W35,100)/100*J35,"")
A36: الإجمالي / Total | J36: =SUM(J5:INDEX(J:J,ROW()-1)) -> 25 | X36: =IF(COUNT(X5:INDEX(X:X,ROW()-1))=0,"",SUM(X5:INDEX(X:X,ROW()-1))) -> 19.025
B38: منظور العمليات الداخلية Internal Process Perspective | E38: العوامل الأساسية / Key Drivers | M38: الإجمالي Total | N38: المخطط والمنجز / Planned & Achieved | V38: النتائج / Results
A39: # | B39: الهدف Objective | C39: مؤشر الأداء KPI | D39: الكود Code | E39: القياس Measurement | F39: دور المؤشر KPI Role | G39: الوحدة Unit | H39: القطبية Polarity | I39: التردد Frequency | J39: الوزن Weight % | K39: خط الأساس Baseline | L39: المستهدف السنوي Annual Target | M39: الإجمالي Total (B+T) | N39: مخطط Q1 Plan | O39: منجز Q1 Actual | P39: مخطط Q2 Plan | Q39: منجز Q2 Actual | R39: مخطط Q3 Plan | S39: منجز Q3 Actual | T39: مخطط Q4 Plan | U39: منجز Q4 Actual | V39: المنجز السنوي Annual Achieved | W39: نسبة الإنجاز Achievement % | X39: النسبة المرجحة Weighted %
A40: =IF(B40="","",COUNTA(B$39:B40)-1) -> 1 | B40: رفع كفاءة الإجراءات | C40: متوسط مدة الاستجابة | D40: =IFERROR(VLOOKUP($F$3,Data!$A:$B,2,0)&"-P"&TEXT(ROW()-ROW($D$39),"0"),"-P"&TEXT(ROW()-ROW($D$39),"0")) -> ZF-P1 | E40: كمي عددي Quantitative Number | F40: نتائج Lagging | G40: أيام Days | H40: تنازلي Descending | I40: ربعي - متوسط Quarterly-Average | J40: 10 | K40: 10 | L40: 5 | M40: =IFERROR(IF(OR(K40="",L40="",ISNUMBER(SEARCH("متوسط",I40)),ISNUMBER(SEARCH("ليكرت",G40)),ISNUMBER(SEARCH("نوعي",E40))),"",K40+L40),"") | N40: 5 | O40: 6 | P40: 5 | Q40: 4 | R40: 5 | T40: 5 | V40: =IFERROR(IF(COUNT(O40,Q40,S40,U40)=0,"",IF(ISNUMBER(SEARCH("تراكمي",I40)),IF(ISNUMBER(U40),U40,IF(ISNUMBER(S40),S40,IF(ISNUMBER(Q40),Q40,O40))),IF(ISNUMBER(SEARCH("متوسط",I40)),AVERAGE(O40,Q40,S40,U40),IF(AND(ISNUMBER(SEARCH("سنوي",I40)),ISERROR(SEARCH("نصف",I40))),IF(ISNUMBER(U40),U40,""),SUM(O40,Q40,S40,U40))))),"-") -> 5 | W40: =IF(OR(NOT(ISNUMBER(L40)),NOT(ISNUMBER(V40))),"",IFERROR(IF(ISNUMBER(SEARCH("تنازلي",H40)), IF(V40=0,100,(L40/V40)*100), (V40/L40)*100),"-")) -> 100 | X40: =IF(AND(ISNUMBER(W40),ISNUMBER(J40)),MIN(W40,100)/100*J40,"") -> 10
A41: =IF(B41="","",COUNTA(B$39:B41)-1) | C41: نسبة إنجاز المشاريع | D41: =IFERROR(VLOOKUP($F$3,Data!$A:$B,2,0)&"-P"&TEXT(ROW()-ROW($D$39),"0"),"-P"&TEXT(ROW()-ROW($D$39),"0")) -> ZF-P2 | E41: كمي نسبي Quantitative % | F41: نتائج Lagging | G41: نسبة % Percentage | H41: تصاعدي Ascending | I41: نصف سنوي - تراكمي Semi-Annual-Cumulative | J41: 10 | K41: 0 | L41: 100 | M41: =IFERROR(IF(OR(K41="",L41="",ISNUMBER(SEARCH("متوسط",I41)),ISNUMBER(SEARCH("ليكرت",G41)),ISNUMBER(SEARCH("نوعي",E41))),"",K41+L41),"") -> 100 | P41: 50 | Q41: 40 | T41: 100 | V41: =IFERROR(IF(COUNT(O41,Q41,S41,U41)=0,"",IF(ISNUMBER(SEARCH("تراكمي",I41)),IF(ISNUMBER(U41),U41,IF(ISNUMBER(S41),S41,IF(ISNUMBER(Q41),Q41,O41))),IF(ISNUMBER(SEARCH("متوسط",I41)),AVERAGE(O41,Q41,S41,U41),IF(AND(ISNUMBER(SEARCH("سنوي",I41)),ISERROR(SEARCH("نصف",I41))),IF(ISNUMBER(U41),U41,""),SUM(O41,Q41,S41,U41))))),"-") -> 40 | W41: =IF(OR(NOT(ISNUMBER(L41)),NOT(ISNUMBER(V41))),"",IFERROR(IF(ISNUMBER(SEARCH("تنازلي",H41)), IF(V41=0,100,(L41/V41)*100), (V41/L41)*100),"-")) -> 40 | X41: =IF(AND(ISNUMBER(W41),ISNUMBER(J41)),MIN(W41,100)/100*J41,"") -> 4
A42: =IF(B42="","",COUNTA(B$39:B42)-1) | C42: عدد الشكاوى | D42: =IFERROR(VLOOKUP($F$3,Data!$A:$B,2,0)&"-P"&TEXT(ROW()-ROW($D$39),"0"),"-P"&TEXT(ROW()-ROW($D$39),"0")) -> ZF-P3 | E42: كمي عددي Quantitative Number | F42: نتائج Lagging | G42: عدد Number | H42: تنازلي Descending | I42: ربعي - مستقل Quarterly-Independent | J42: 5 | K42: 30 | L42: 20 | M42: =IFERROR(IF(OR(K42="",L42="",ISNUMBER(SEARCH("متوسط",I42)),ISNUMBER(SEARCH("ليكرت",G42)),ISNUMBER(SEARCH("نوعي",E42))),"",K42+L42),"") -> 50 | N42: 5 | O42: 0 | P42: 5 | Q42: 0 | R42: 5 | T42: 5 | V42: =IFERROR(IF(COUNT(O42,Q42,S42,U42)=0,"",IF(ISNUMBER(SEARCH("تراكمي",I42)),IF(ISNUMBER(U42),U42,IF(ISNUMBER(S42),S42,IF(ISNUMBER(Q42),Q42,O42))),IF(ISNUMBER(SEARCH("متوسط",I42)),AVERAGE(O42,Q42,S42,U42),IF(AND(ISNUMBER(SEARCH("سنوي",I42)),ISERROR(SEARCH("نصف",I42))),IF(ISNUMBER(U42),U42,""),SUM(O42,Q42,S42,U42))))),"-") -> 0 | W42: =IF(OR(NOT(ISNUMBER(L42)),NOT(ISNUMBER(V42))),"",IFERROR(IF(ISNUMBER(SEARCH("تنازلي",H42)), IF(V42=0,100,(L42/V42)*100), (V42/L42)*100),"-")) -> 100 | X42: =IF(AND(ISNUMBER(W42),ISNUMBER(J42)),MIN(W42,100)/100*J42,"") -> 5
A43: =IF(B43="","",COUNTA(B$39:B43)-1) | D43: =IFERROR(VLOOKUP($F$3,Data!$A:$B,2,0)&"-P"&TEXT(ROW()-ROW($D$39),"0"),"-P"&TEXT(ROW()-ROW($D$39),"0")) -> ZF-P4 | M43: =IFERROR(IF(OR(K43="",L43="",ISNUMBER(SEARCH("متوسط",I43)),ISNUMBER(SEARCH("ليكرت",G43)),ISNUMBER(SEARCH("نوعي",E43))),"",K43+L43),"") | V43: =IFERROR(IF(COUNT(O43,Q43,S43,U43)=0,"",IF(ISNUMBER(SEARCH("تراكمي",I43)),IF(ISNUMBER(U43),U43,IF(ISNUMBER(S43),S43,IF(ISNUMBER(Q43),Q43,O43))),IF(ISNUMBER(SEARCH("متوسط",I43)),AVERAGE(O43,Q43,S43,U43),IF(AND(ISNUMBER(SEARCH("سنوي",I43)),ISERROR(SEARCH("نصف",I43))),IF(ISNUMBER(U43),U43,""),SUM(O43,Q43,S43,U43))))),"-") | W43: =IF(OR(NOT(ISNUMBER(L43)),NOT(ISNUMBER(V43))),"",IFERROR(IF(ISNUMBER(SEARCH("تنازلي",H43)), IF(V43=0,100,(L43/V43)*100), (V43/L43)*100),"-")) | X43: =IF(AND(ISNUMBER(W43),ISNUMBER(J43)),MIN(W43,100)/100*J43,"")
A44: =IF(B44="","",COUNTA(B$39:B44)-1) | D44: =IFERROR(VLOOKUP($F$3,Data!$A:$B,2,0)&"-P"&TEXT(ROW()-ROW($D$39),"0"),"-P"&TEXT(ROW()-ROW($D$39),"0")) -> ZF-P5 | M44: =IFERROR(IF(OR(K44="",L44="",ISNUMBER(SEARCH("متوسط",I44)),ISNUMBER(SEARCH("ليكرت",G44)),ISNUMBER(SEARCH("نوعي",E44))),"",K44+L44),"") | V44: =IFERROR(IF(COUNT(O44,Q44,S44,U44)=0,"",IF(ISNUMBER(SEARCH("تراكمي",I44)),IF(ISNUMBER(U44),U44,IF(ISNUMBER(S44),S44,IF(ISNUMBER(Q44),Q44,O44))),IF(ISNUMBER(SEARCH("متوسط",I44)),AVERAGE(O44,Q44,S44,U44),IF(AND(ISNUMBER(SEARCH("سنوي",I44)),ISERROR(SEARCH("نصف",I44))),IF(ISNUMBER(U44),U44,""),SUM(O44,Q44,S44,U44))))),"-") | W44: =IF(OR(NOT(ISNUMBER(L44)),NOT(ISNUMBER(V44))),"",IFERROR(IF(ISNUMBER(SEARCH("تنازلي",H44)), IF(V44=0,100,(L44/V44)*100), (V44/L44)*100),"-")) | X44: =IF(AND(ISNUMBER(W44),ISNUMBER(J44)),MIN(W44,100)/100*J44,"")
A45: =IF(B45="","",COUNTA(B$39:B45)-1) | D45: =IFERROR(VLOOKUP($F$3,Data!$A:$B,2,0)&"-P"&TEXT(ROW()-ROW($D$39),"0"),"-P"&TEXT(ROW()-ROW($D$39),"0")) -> ZF-P6 | M45: =IFERROR(IF(OR(K45="",L45="",ISNUMBER(SEARCH("متوسط",I45)),ISNUMBER(SEARCH("ليكرت",G45)),ISNUMBER(SEARCH("نوعي",E45))),"",K45+L45),"") | V45: =IFERROR(IF(COUNT(O45,Q45,S45,U45)=0,"",IF(ISNUMBER(SEARCH("تراكمي",I45)),IF(ISNUMBER(U45),U45,IF(ISNUMBER(S45),S45,IF(ISNUMBER(Q45),Q45,O45))),IF(ISNUMBER(SEARCH("متوسط",I45)),AVERAGE(O45,Q45,S45,U45),IF(AND(ISNUMBER(SEARCH("سنوي",I45)),ISERROR(SEARCH("نصف",I45))),IF(ISNUMBER(U45),U45,""),SUM(O45,Q45,S45,U45))))),"-") | W45: =IF(OR(NOT(ISNUMBER(L45)),NOT(ISNUMBER(V45))),"",IFERROR(IF(ISNUMBER(SEARCH("تنازلي",H45)), IF(V45=0,100,(L45/V45)*100), (V45/L45)*100),"-")) | X45: =IF(AND(ISNUMBER(W45),ISNUMBER(J45)),MIN(W45,100)/100*J45,"")
A46: =IF(B46="","",COUNTA(B$39:B46)-1) | D46: =IFERROR(VLOOKUP($F$3,Data!$A:$B,2,0)&"-P"&TEXT(ROW()-ROW($D$39),"0"),"-P"&TEXT(ROW()-ROW($D$39),"0")) -> ZF-P7 | M46: =IFERROR(IF(OR(K46="",L46="",ISNUMBER(SEARCH("متوسط",I46)),ISNUMBER(SEARCH("ليكرت",G46)),ISNUMBER(SEARCH("نوعي",E46))),"",K46+L46),"") | V46: =IFERROR(IF(COUNT(O46,Q46,S46,U46)=0,"",IF(ISNUMBER(SEARCH("تراكمي",I46)),IF(ISNUMBER(U46),U46,IF(ISNUMBER(S46),S46,IF(ISNUMBER(Q46),Q46,O46))),IF(ISNUMBER(SEARCH("متوسط",I46)),AVERAGE(O46,Q46,S46,U46),IF(AND(ISNUMBER(SEARCH("سنوي",I46)),ISERROR(SEARCH("نصف",I46))),IF(ISNUMBER(U46),U46,""),SUM(O46,Q46,S46,U46))))),"-") | W46: =IF(OR(NOT(ISNUMBER(L46)),NOT(ISNUMBER(V46))),"",IFERROR(IF(ISNUMBER(SEARCH("تنازلي",H46)), IF(V46=0,100,(L46/V46)*100), (V46/L46)*100),"-")) | X46: =IF(AND(ISNUMBER(W46),ISNUMBER(J46)),MIN(W46,100)/100*J46,"")
A47: =IF(B47="","",COUNTA(B$39:B47)-1) | D47: =IFERROR(VLOOKUP($F$3,Data!$A:$B,2,0)&"-P"&TEXT(ROW()-ROW($D$39),"0"),"-P"&TEXT(ROW()-ROW($D$39),"0")) -> ZF-P8 | M47: =IFERROR(IF(OR(K47="",L47="",ISNUMBER(SEARCH("متوسط",I47)),ISNUMBER(SEARCH("ليكرت",G47)),ISNUMBER(SEARCH("نوعي",E47))),"",K47+L47),"") | V47: =IFERROR(IF(COUNT(O47,Q47,S47,U47)=0,"",IF(ISNUMBER(SEARCH("تراكمي",I47)),IF(ISNUMBER(U47),U47,IF(ISNUMBER(S47),S47,IF(ISNUMBER(Q47),Q47,O47))),IF(ISNUMBER(SEARCH("متوسط",I47)),AVERAGE(O47,Q47,S47,U47),IF(AND(ISNUMBER(SEARCH("سنوي",I47)),ISERROR(SEARCH("نصف",I47))),IF(ISNUMBER(U47),U47,""),SUM(O47,Q47,S47,U47))))),"-") | W47: =IF(OR(NOT(ISNUMBER(L47)),NOT(ISNUMBER(V47))),"",IFERROR(IF(ISNUMBER(SEARCH("تنازلي",H47)), IF(V47=0,100,(L47/V47)*100), (V47/L47)*100),"-")) | X47: =IF(AND(ISNUMBER(W47),ISNUMBER(J47)),MIN(W47,100)/100*J47,"")
A48: =IF(B48="","",COUNTA(B$39:B48)-1) | D48: =IFERROR(VLOOKUP($F$3,Data!$A:$B,2,0)&"-P"&TEXT(ROW()-ROW($D$39),"0"),"-P"&TEXT(ROW()-ROW($D$39),"0")) -> ZF-P9 | M48: =IFERROR(IF(OR(K48="",L48="",ISNUMBER(SEARCH("متوسط",I48)),ISNUMBER(SEARCH("ليكرت",G48)),ISNUMBER(SEARCH("نوعي",E48))),"",K48+L48),"") | V48: =IFERROR(IF(COUNT(O48,Q48,S48,U48)=0,"",IF(ISNUMBER(SEARCH("تراكمي",I48)),IF(ISNUMBER(U48),U48,IF(ISNUMBER(S48),S48,IF(ISNUMBER(Q48),Q48,O48))),IF(ISNUMBER(SEARCH("متوسط",I48)),AVERAGE(O48,Q48,S48,U48),IF(AND(ISNUMBER(SEARCH("سنوي",I48)),ISERROR(SEARCH("نصف",I48))),IF(ISNUMBER(U48),U48,""),SUM(O48,Q48,S48,U48))))),"-") | W48: =IF(OR(NOT(ISNUMBER(L48)),NOT(ISNUMBER(V48))),"",IFERROR(IF(ISNUMBER(SEARCH("تنازلي",H48)), IF(V48=0,100,(L48/V48)*100), (V48/L48)*100),"-")) | X48: =IF(AND(ISNUMBER(W48),ISNUMBER(J48)),MIN(W48,100)/100*J48,"")
A49: =IF(B49="","",COUNTA(B$39:B49)-1) | D49: =IFERROR(VLOOKUP($F$3,Data!$A:$B,2,0)&"-P"&TEXT(ROW()-ROW($D$39),"0"),"-P"&TEXT(ROW()-ROW($D$39),"0")) -> ZF-P10 | M49: =IFERROR(IF(OR(K49="",L49="",ISNUMBER(SEARCH("متوسط",I49)),ISNUMBER(SEARCH("ليكرت",G49)),ISNUMBER(SEARCH("نوعي",E49))),"",K49+L49),"") | V49: =IFERROR(IF(COUNT(O49,Q49,S49,U49)=0,"",IF(ISNUMBER(SEARCH("تراكمي",I49)),IF(ISNUMBER(U49),U49,IF(ISNUMBER(S49),S49,IF(ISNUMBER(Q49),Q49,O49))),IF(ISNUMBER(SEARCH("متوسط",I49)),AVERAGE(O49,Q49,S49,U49),IF(AND(ISNUMBER(SEARCH("سنوي",I49)),ISERROR(SEARCH("نصف",I49))),IF(ISNUMBER(U49),U49,""),SUM(O49,Q49,S49,U49))))),"-") | W49: =IF(OR(NOT(ISNUMBER(L49)),NOT(ISNUMBER(V49))),"",IFERROR(IF(ISNUMBER(SEARCH("تنازلي",H49)), IF(V49=0,100,(L49/V49)*100), (V49/L49)*100),"-")) | X49: =IF(AND(ISNUMBER(W49),ISNUMBER(J49)),MIN(W49,100)/100*J49,"")
A50: =IF(B50="","",COUNTA(B$39:B50)-1) | D50: =IFERROR(VLOOKUP($F$3,Data!$A:$B,2,0)&"-P"&TEXT(ROW()-ROW($D$39),"0"),"-P"&TEXT(ROW()-ROW($D$39),"0")) -> ZF-P11 | M50: =IFERROR(IF(OR(K50="",L50="",ISNUMBER(SEARCH("متوسط",I50)),ISNUMBER(SEARCH("ليكرت",G50)),ISNUMBER(SEARCH("نوعي",E50))),"",K50+L50),"") | V50: =IFERROR(IF(COUNT(O50,Q50,S50,U50)=0,"",IF(ISNUMBER(SEARCH("تراكمي",I50)),IF(ISNUMBER(U50),U50,IF(ISNUMBER(S50),S50,IF(ISNUMBER(Q50),Q50,O50))),IF(ISNUMBER(SEARCH("متوسط",I50)),AVERAGE(O50,Q50,S50,U50),IF(AND(ISNUMBER(SEARCH("سنوي",I50)),ISERROR(SEARCH("نصف",I50))),IF(ISNUMBER(U50),U50,""),SUM(O50,Q50,S50,U50))))),"-") | W50: =IF(OR(NOT(ISNUMBER(L50)),NOT(ISNUMBER(V50))),"",IFERROR(IF(ISNUMBER(SEARCH("تنازلي",H50)), IF(V50=0,100,(L50/V50)*100), (V50/L50)*100),"-")) | X50: =IF(AND(ISNUMBER(W50),ISNUMBER(J50)),MIN(W50,100)/100*J50,"")
A51: =IF(B51="","",COUNTA(B$39:B51)-1) | D51: =IFERROR(VLOOKUP($F$3,Data!$A:$B,2,0)&"-P"&TEXT(ROW()-ROW($D$39),"0"),"-P"&TEXT(ROW()-ROW($D$39),"0")) -> ZF-P12 | M51: =IFERROR(IF(OR(K51="",L51="",ISNUMBER(SEARCH("متوسط",I51)),ISNUMBER(SEARCH("ليكرت",G51)),ISNUMBER(SEARCH("نوعي",E51))),"",K51+L51),"") | V51: =IFERROR(IF(COUNT(O51,Q51,S51,U51)=0,"",IF(ISNUMBER(SEARCH("تراكمي",I51)),IF(ISNUMBER(U51),U51,IF(ISNUMBER(S51),S51,IF(ISNUMBER(Q51),Q51,O51))),IF(ISNUMBER(SEARCH("متوسط",I51)),AVERAGE(O51,Q51,S51,U51),IF(AND(ISNUMBER(SEARCH("سنوي",I51)),ISERROR(SEARCH("نصف",I51))),IF(ISNUMBER(U51),U51,""),SUM(O51,Q51,S51,U51))))),"-") | W51: =IF(OR(NOT(ISNUMBER(L51)),NOT(ISNUMBER(V51))),"",IFERROR(IF(ISNUMBER(SEARCH("تنازلي",H51)), IF(V51=0,100,(L51/V51)*100), (V51/L51)*100),"-")) | X51: =IF(AND(ISNUMBER(W51),ISNUMBER(J51)),MIN(W51,100)/100*J51,"")
A52: =IF(B52="","",COUNTA(B$39:B52)-1) | D52: =IFERROR(VLOOKUP($F$3,Data!$A:$B,2,0)&"-P"&TEXT(ROW()-ROW($D$39),"0"),"-P"&TEXT(ROW()-ROW($D$39),"0")) -> ZF-P13 | M52: =IFERROR(IF(OR(K52="",L52="",ISNUMBER(SEARCH("متوسط",I52)),ISNUMBER(SEARCH("ليكرت",G52)),ISNUMBER(SEARCH("نوعي",E52))),"",K52+L52),"") | V52: =IFERROR(IF(COUNT(O52,Q52,S52,U52)=0,"",IF(ISNUMBER(SEARCH("تراكمي",I52)),IF(ISNUMBER(U52),U52,IF(ISNUMBER(S52),S52,IF(ISNUMBER(Q52),Q52,O52))),IF(ISNUMBER(SEARCH("متوسط",I52)),AVERAGE(O52,Q52,S52,U52),IF(AND(ISNUMBER(SEARCH("سنوي",I52)),ISERROR(SEARCH("نصف",I52))),IF(ISNUMBER(U52),U52,""),SUM(O52,Q52,S52,U52))))),"-") | W52: =IF(OR(NOT(ISNUMBER(L52)),NOT(ISNUMBER(V52))),"",IFERROR(IF(ISNUMBER(SEARCH("تنازلي",H52)), IF(V52=0,100,(L52/V52)*100), (V52/L52)*100),"-")) | X52: =IF(AND(ISNUMBER(W52),ISNUMBER(J52)),MIN(W52,100)/100*J52,"")
A53: =IF(B53="","",COUNTA(B$39:B53)-1) | D53: =IFERROR(VLOOKUP($F$3,Data!$A:$B,2,0)&"-P"&TEXT(ROW()-ROW($D$39),"0"),"-P"&TEXT(ROW()-ROW($D$39),"0")) -> ZF-P14 | M53: =IFERROR(IF(OR(K53="",L53="",ISNUMBER(SEARCH("متوسط",I53)),ISNUMBER(SEARCH("ليكرت",G53)),ISNUMBER(SEARCH("نوعي",E53))),"",K53+L53),"") | V53: =IFERROR(IF(COUNT(O53,Q53,S53,U53)=0,"",IF(ISNUMBER(SEARCH("تراكمي",I53)),IF(ISNUMBER(U53),U53,IF(ISNUMBER(S53),S53,IF(ISNUMBER(Q53),Q53,O53))),IF(ISNUMBER(SEARCH("متوسط",I53)),AVERAGE(O53,Q53,S53,U53),IF(AND(ISNUMBER(SEARCH("سنوي",I53)),ISERROR(SEARCH("نصف",I53))),IF(ISNUMBER(U53),U53,""),SUM(O53,Q53,S53,U53))))),"-") | W53: =IF(OR(NOT(ISNUMBER(L53)),NOT(ISNUMBER(V53))),"",IFERROR(IF(ISNUMBER(SEARCH("تنازلي",H53)), IF(V53=0,100,(L53/V53)*100), (V53/L53)*100),"-")) | X53: =IF(AND(ISNUMBER(W53),ISNUMBER(J53)),MIN(W53,100)/100*J53,"")
A54: =IF(B54="","",COUNTA(B$39:B54)-1) | D54: =IFERROR(VLOOKUP($F$3,Data!$A:$B,2,0)&"-P"&TEXT(ROW()-ROW($D$39),"0"),"-P"&TEXT(ROW()-ROW($D$39),"0")) -> ZF-P15 | M54: =IFERROR(IF(OR(K54="",L54="",ISNUMBER(SEARCH("متوسط",I54)),ISNUMBER(SEARCH("ليكرت",G54)),ISNUMBER(SEARCH("نوعي",E54))),"",K54+L54),"") | V54: =IFERROR(IF(COUNT(O54,Q54,S54,U54)=0,"",IF(ISNUMBER(SEARCH("تراكمي",I54)),IF(ISNUMBER(U54),U54,IF(ISNUMBER(S54),S54,IF(ISNUMBER(Q54),Q54,O54))),IF(ISNUMBER(SEARCH("متوسط",I54)),AVERAGE(O54,Q54,S54,U54),IF(AND(ISNUMBER(SEARCH("سنوي",I54)),ISERROR(SEARCH("نصف",I54))),IF(ISNUMBER(U54),U54,""),SUM(O54,Q54,S54,U54))))),"-") | W54: =IF(OR(NOT(ISNUMBER(L54)),NOT(ISNUMBER(V54))),"",IFERROR(IF(ISNUMBER(SEARCH("تنازلي",H54)), IF(V54=0,100,(L54/V54)*100), (V54/L54)*100),"-")) | X54: =IF(AND(ISNUMBER(W54),ISNUMBER(J54)),MIN(W54,100)/100*J54,"")
... A69: =IF(B69="","",COUNTA(B$39:B69)-1) | D69: =IFERROR(VLOOKUP($F$3,Data!$A:$B,2,0)&"-P"&TEXT(ROW()-ROW($D$39),"0"),"-P"&TEXT(ROW()-ROW($D$39),"0")) -> ZF-P30 | M69: =IFERROR(IF(OR(K69="",L69="",ISNUMBER(SEARCH("متوسط",I69)),ISNUMBER(SEARCH("ليكرت",G69)),ISNUMBER(SEARCH("نوعي",E69))),"",K69+L69),"") | V69: =IFERROR(IF(COUNT(O69,Q69,S69,U69)=0,"",IF(ISNUMBER(SEARCH("تراكمي",I69)),IF(ISNUMBER(U69),U69,IF(ISNUMBER(S69),S69,IF(ISNUMBER(Q69),Q69,O69))),IF(ISNUMBER(SEARCH("متوسط",I69)),AVERAGE(O69,Q69,S69,U69),IF(AND(ISNUMBER(SEARCH("سنوي",I69)),ISERROR(SEARCH("نصف",I69))),IF(ISNUMBER(U69),U69,""),SUM(O69,Q69,S69,U69))))),"-") | W69: =IF(OR(NOT(ISNUMBER(L69)),NOT(ISNUMBER(V69))),"",IFERROR(IF(ISNUMBER(SEARCH("تنازلي",H69)), IF(V69=0,100,(L69/V69)*100), (V69/L69)*100),"-")) | X69: =IF(AND(ISNUMBER(W69),ISNUMBER(J69)),MIN(W69,100)/100*J69,"")
...

Sheet الأنشطة
A1: مكتب الإشراف والتطوير المؤسسي (OID) Oversight and Institutional Development
A2: تقرير تنفيذ الخطة التشغيلية / Operational Plan Implementation Report
A3: اسم المؤسسة Institution | D3: =IF('KPI Tracking'!F3="","",'KPI Tracking'!F3) -> مؤسسة زمزم Zamzam Foundation | F3: الفترة Period | G3: =IF('KPI Tracking'!P3="","",'KPI Tracking'!P3) -> Q2 | H3: تُختار المؤسسة والفترة من رأس ورقة KPI Tracking / Institution and period are selected in the KPI Tracking sheet
A5: سجل البرامج والأنشطة / Programs & Activities Register
A6: # | B6: الفترة Period | C6: النوع Type | D6: البرنامج / النشاط Program / Activity | E6: الفئة المستهدفة Target Group | F6: الجهة المنفذة Implementer | G6: المستفيدون / المشاركون Beneficiaries / Participants | H6: المخطط Planned | I6: المنجز Achieved | J6: نسبة الإنجاز Achievement % | K6: كود المؤشر الداعم Supporting KPI Code
A7: =IF(D7="","",COUNTA(D$7:D7)) -> 1 | B7: Q1 | C7: برنامج / مشروع / نشاط Program / Project / Activity | D7: برنامج سبل العيش | E7: الأسر | F7: فريق البرامج | G7: 200 | H7: 5 | I7: 4 | J7: =IF(AND(ISNUMBER(H7),ISNUMBER(I7),H7<>0),I7/H7,"") -> 0.8 | K7: ZF-S2
A8: =IF(D8="","",COUNTA(D$7:D8)) -> 2 | B8: Q2 | C8: برنامج / مشروع / نشاط Program / Project / Activity | D8: برنامج سبل العيش | E8: الأسر | F8: فريق البرامج | G8: 300 | H8: 6 | I8: 6 | J8: =IF(AND(ISNUMBER(H8),ISNUMBER(I8),H8<>0),I8/H8,"") -> 1 | K8: ZF-S2
A9: =IF(D9="","",COUNTA(D$7:D9)) -> 3 | B9: Q2 | C9: فعالية مجتمعية Community Event | D9: يوم مجتمعي | E9: المجتمع المحلي | F9: العلاقات العامة | G9: 150 | H9: 2 | I9: 3 | J9: =IF(AND(ISNUMBER(H9),ISNUMBER(I9),H9<>0),I9/H9,"") -> 1.5 | K9: ZF-S1
A10: =IF(D10="","",COUNTA(D$7:D10)) -> 4 | B10: Q1 | C10: تدريب وبناء قدرات Training & Capacity Building | D10: دورة إدارة المشاريع | E10: الموظفون | F10: الموارد البشرية | G10: 25 | H10: 2 | I10: 2 | J10: =IF(AND(ISNUMBER(H10),ISNUMBER(I10),H10<>0),I10/H10,"") -> 1 | K10: ZF-L2
A11: =IF(D11="","",COUNTA(D$7:D11)) -> 5 | B11: Q3 | C11: تدريب وبناء قدرات Training & Capacity Building | D11: دورة الحوكمة | E11: الموظفون | F11: الموارد البشرية | G11: 30 | H11: 4 | J11: =IF(AND(ISNUMBER(H11),ISNUMBER(I11),H11<>0),I11/H11,"") | K11: ZF-L2
A12: =IF(D12="","",COUNTA(D$7:D12)) | J12: =IF(AND(ISNUMBER(H12),ISNUMBER(I12),H12<>0),I12/H12,"")
A13: =IF(D13="","",COUNTA(D$7:D13)) | J13: =IF(AND(ISNUMBER(H13),ISNUMBER(I13),H13<>0),I13/H13,"")
A14: =IF(D14="","",COUNTA(D$7:D14)) | J14: =IF(AND(ISNUMBER(H14),ISNUMBER(I14),H14<>0),I14/H14,"")
A15: =IF(D15="","",COUNTA(D$7:D15)) | J15: =IF(AND(ISNUMBER(H15),ISNUMBER(I15),H15<>0),I15/H15,"")
A16: =IF(D16="","",COUNTA(D$7:D16)) | J16: =IF(AND(ISNUMBER(H16),ISNUMBER(I16),H16<>0),I16/H16,"")
A17: =IF(D17="","",COUNTA(D$7:D17)) | J17: =IF(AND(ISNUMBER(H17),ISNUMBER(I17),H17<>0),I17/H17,"")
A18: =IF(D18="","",COUNTA(D$7:D18)) | J18: =IF(AND(ISNUMBER(H18),ISNUMBER(I18),H18<>0),I18/H18,"")
A19: =IF(D19="","",COUNTA(D$7:D19)) | J19: =IF(AND(ISNUMBER(H19),ISNUMBER(I19),H19<>0),I19/H19,"")
A20: =IF(D20="","",COUNTA(D$7:D20)) | J20: =IF(AND(ISNUMBER(H20),ISNUMBER(I20),H20<>0),I20/H20,"")
A21: =IF(D21="","",COUNTA(D$7:D21)) | J21: =IF(AND(ISNUMBER(H21),ISNUMBER(I21),H21<>0),I21/H21,"")
A22: =IF(D22="","",COUNTA(D$7:D22)) | J22: =IF(AND(ISNUMBER(H22),ISNUMBER(I22),H22<>0),I22/H22,"")
A23: =IF(D23="","",COUNTA(D$7:D23)) | J23: =IF(AND(ISNUMBER(H23),ISNUMBER(I23),H23<>0),I23/H23,"")
... A86: =IF(D86="","",COUNTA(D$7:D86)) | J86: =IF(AND(ISNUMBER(H86),ISNUMBER(I86),H86<>0),I86/H86,"")
A88: الإجماليات حسب النوع / Totals by Type
A89: البند / Item | G89: المستفيدون / المشاركون Beneficiaries / Participants | H89: المخطط Planned | I89: المنجز Achieved | J89: نسبة الإنجاز Achievement %
A90: الفترة المختارة / Selected Period: برنامج / مشروع / نشاط — Program / Project / Activity | G90: =IF($G$3="","",SUMIFS(G7:G86,$B7:$B86,$G$3,$C7:$C86,Data!$AG$2)) -> 300 | H90: =IF($G$3="","",SUMIFS(H7:H86,$B7:$B86,$G$3,$C7:$C86,Data!$AG$2)) -> 6 | I90: =IF($G$3="","",SUMIFS(I7:I86,$B7:$B86,$G$3,$C7:$C86,Data!$AG$2)) -> 6 | J90: =IFERROR(IF(H90=0,"-",I90/H90),"-") -> 1
A91: الفترة المختارة / Selected Period: فعالية مجتمعية — Community Event | G91: =IF($G$3="","",SUMIFS(G7:G86,$B7:$B86,$G$3,$C7:$C86,Data!$AG$3)) -> 150 | H91: =IF($G$3="","",SUMIFS(H7:H86,$B7:$B86,$G$3,$C7:$C86,Data!$AG$3)) -> 2 | I91: =IF($G$3="","",SUMIFS(I7:I86,$B7:$B86,$G$3,$C7:$C86,Data!$AG$3)) -> 3 | J91: =IFERROR(IF(H91=0,"-",I91/H91),"-") -> 1.5
A92: الفترة المختارة / Selected Period: تدريب وبناء قدرات — Training & Capacity Building | G92: =IF($G$3="","",SUMIFS(G7:G86,$B7:$B86,$G$3,$C7:$C86,Data!$AG$4)) -> 0 | H92: =IF($G$3="","",SUMIFS(H7:H86,$B7:$B86,$G$3,$C7:$C86,Data!$AG$4)) -> 0 | I92: =IF($G$3="","",SUMIFS(I7:I86,$B7:$B86,$G$3,$C7:$C86,Data!$AG$4)) -> 0 | J92: =IFERROR(IF(H92=0,"-",I92/H92),"-") -> -
A93: الفترة المختارة / Selected Period: الإجمالي / Total | G93: =IF($G$3="","",SUMIFS(G7:G86,$B7:$B86,$G$3)) -> 450 | H93: =IF($G$3="","",SUMIFS(H7:H86,$B7:$B86,$G$3)) -> 8 | I93: =IF($G$3="","",SUMIFS(I7:I86,$B7:$B86,$G$3)) -> 9 | J93: =IFERROR(IF(H93=0,"-",I93/H93),"-") -> 1.125
A94: السنة كاملة / Full Year: برنامج / مشروع / نشاط — Program / Project / Activity | G94: =SUMIFS(G7:G86,$C7:$C86,Data!$AG$2) -> 500 | H94: =SUMIFS(H7:H86,$C7:$C86,Data!$AG$2) -> 11 | I94: =SUMIFS(I7:I86,$C7:$C86,Data!$AG$2) -> 10 | J94: =IFERROR(IF(H94=0,"-",I94/H94),"-") -> 0.90909091
A95: السنة كاملة / Full Year: فعالية مجتمعية — Community Event | G95: =SUMIFS(G7:G86,$C7:$C86,Data!$AG$3) -> 150 | H95: =SUMIFS(H7:H86,$C7:$C86,Data!$AG$3) -> 2 | I95: =SUMIFS(I7:I86,$C7:$C86,Data!$AG$3) -> 3 | J95: =IFERROR(IF(H95=0,"-",I95/H95),"-") -> 1.5
A96: السنة كاملة / Full Year: تدريب وبناء قدرات — Training & Capacity Building | G96: =SUMIFS(G7:G86,$C7:$C86,Data!$AG$4) -> 55 | H96: =SUMIFS(H7:H86,$C7:$C86,Data!$AG$4) -> 6 | I96: =SUMIFS(I7:I86,$C7:$C86,Data!$AG$4) -> 2 | J96: =IFERROR(IF(H96=0,"-",I96/H96),"-") -> 0.33333333
A97: السنة كاملة / Full Year: الإجمالي / Total | G97: =SUM(G7:G86) -> 705 | H97: =SUM(H7:H86) -> 19 | I97: =SUM(I7:I86) -> 15 | J97: =IFERROR(IF(H97=0,"-",I97/H97),"-") -> 0.78947368

Sheet الملخص
A1: مكتب الإشراف والتطوير المؤسسي (OID) Oversight and Institutional Development
A2: تقرير الأداء الربعي والسنوي Quarterly & Annual Performance Report
B3: اسم المؤسسة Name of the institution | C3: الفترة Period | D3: معدّ التقرير Report writer | E3: مراجعة واعتماد Review and approval
B4: =IF('KPI Tracking'!F3="","",'KPI Tracking'!F3) -> مؤسسة زمزم Zamzam Foundation | C4: =IF('KPI Tracking'!P3="","",'KPI Tracking'!P3) -> Q2
A5: الملخص التنفيذي Executive Summary
A6: ملخص تنفيذي تجريبي للربع الثاني.
A7: نتيجة مؤشرات الأداء الرئيسية / KPI Overall Result
A8: # | B8: المنظور Perspective | C8: الوزن % Weight % | D8: الدرجة المحققة Score Achieved | E8: الدرجة المرجحة Weighted Score | F8: التقييم Rating | G8: ملاحظات Notes
A9: 1 | B9: منظور أصحاب المصلحة Stakeholder Perspective | C9: =N('KPI Tracking'!J36)/100 -> 0.25 | D9: =IFERROR(E9/C9,0) -> 0.761 | E9: =N('KPI Tracking'!X36)/100 -> 0.19025 | F9: =IF(AND(ISNUMBER(D9),C9>0),LOOKUP(D9,Data!$AD$2:$AD$5,Data!$AE$2:$AE$5),"") -> جيد Good
A10: 2 | B10: العمليات الداخلية Internal Processes | C10: =N('KPI Tracking'!J70)/100 -> 0.25 | D10: =IFERROR(E10/C10,0) -> 0.76 | E10: =N('KPI Tracking'!X70)/100 -> 0.19 | F10: =IF(AND(ISNUMBER(D10),C10>0),LOOKUP(D10,Data!$AD$2:$AD$5,Data!$AE$2:$AE$5),"") -> جيد Good
A11: 3 | B11: التعلم والنمو Learning & Growth | C11: =N('KPI Tracking'!J104)/100 -> 0.25 | D11: =IFERROR(E11/C11,0) -> 0.6 | E11: =N('KPI Tracking'!X104)/100 -> 0.15 | F11: =IF(AND(ISNUMBER(D11),C11>0),LOOKUP(D11,Data!$AD$2:$AD$5,Data!$AE$2:$AE$5),"") -> متوسط Average
A12: 4 | B12: المنظور المالي Financial Perspective | C12: =N('KPI Tracking'!J138)/100 -> 0.25 | D12: =IFERROR(E12/C12,0) -> 0.67894737 | E12: =N('KPI Tracking'!X138)/100 -> 0.16973684 | F12: =IF(AND(ISNUMBER(D12),C12>0),LOOKUP(D12,Data!$AD$2:$AD$5,Data!$AE$2:$AE$5),"") -> متوسط Average
A13: الدرجة الإجمالية / Overall Score | C13: =IFERROR(SUM(C9:C12),0) -> 1 | D13: =IFERROR(E13/C13,0) -> 0.69998684 | E13: =IFERROR(SUM(E9:E12),0) -> 0.69998684 | F13: =IF(AND(ISNUMBER(D13),C13>0),LOOKUP(D13,Data!$AD$2:$AD$5,Data!$AE$2:$AE$5),"") -> متوسط Average
A15: ملخص الخطة التشغيلية / Operational Plan Summary
A16: # | B16: البيان Item | C16: المخطط Planned | D16: المنجز Achieved | E16: نسبة الإنجاز Achievement % | F16: التقييم Rating | G16: الملاحظة Note
A17: =ROW()-ROW($A$16) -> 1 | B17: البرامج والمشاريع والأنشطة المنفذة | Programs/Projects/Activities | C17: =IF('KPI Tracking'!$P$3="",SUMIFS(الأنشطة!H7:H86,الأنشطة!C7:C86,Data!$AG$2),SUMPRODUCT((الأنشطة!B7:B86<>"")*(RIGHT(الأنشطة!B7:B86,1)<=RIGHT('KPI Tracking'!$P$3,1))*(الأنشطة!C7:C86=Data!$AG$2)*الأنشطة!H7:H86)) -> 11 | D17: =IF('KPI Tracking'!$P$3="",SUMIFS(الأنشطة!I7:I86,الأنشطة!C7:C86,Data!$AG$2),SUMPRODUCT((الأنشطة!B7:B86<>"")*(RIGHT(الأنشطة!B7:B86,1)<=RIGHT('KPI Tracking'!$P$3,1))*(الأنشطة!C7:C86=Data!$AG$2)*الأنشطة!I7:I86)) -> 10 | E17: =IFERROR(D17/C17,"-") -> 0.90909091 | F17: =IF(ISNUMBER(E17),LOOKUP(E17,Data!$AD$2:$AD$5,Data!$AE$2:$AE$5),"") -> ممتاز Excellent
A18: =ROW()-ROW($A$16) -> 2 | B18: المستفيدون الفعليون | Beneficiaries Reached | C18: 600 | D18: =IF('KPI Tracking'!$P$3="",SUMIFS(الأنشطة!G7:G86,الأنشطة!C7:C86,Data!$AG$2),SUMPRODUCT((الأنشطة!B7:B86<>"")*(RIGHT(الأنشطة!B7:B86,1)<=RIGHT('KPI Tracking'!$P$3,1))*(الأنشطة!C7:C86=Data!$AG$2)*الأنشطة!G7:G86)) -> 500 | E18: =IFERROR(D18/C18,"-") -> 0.83333333 | F18: =IF(ISNUMBER(E18),LOOKUP(E18,Data!$AD$2:$AD$5,Data!$AE$2:$AE$5),"") -> جيد Good
A19: =ROW()-ROW($A$16) -> 3 | B19: الفعاليات والأنشطة المجتمعية | Events & Engagement | C19: =IF('KPI Tracking'!$P$3="",SUMIFS(الأنشطة!H7:H86,الأنشطة!C7:C86,Data!$AG$3),SUMPRODUCT((الأنشطة!B7:B86<>"")*(RIGHT(الأنشطة!B7:B86,1)<=RIGHT('KPI Tracking'!$P$3,1))*(الأنشطة!C7:C86=Data!$AG$3)*الأنشطة!H7:H86)) -> 2 | D19: =IF('KPI Tracking'!$P$3="",SUMIFS(الأنشطة!I7:I86,الأنشطة!C7:C86,Data!$AG$3),SUMPRODUCT((الأنشطة!B7:B86<>"")*(RIGHT(الأنشطة!B7:B86,1)<=RIGHT('KPI Tracking'!$P$3,1))*(الأنشطة!C7:C86=Data!$AG$3)*الأنشطة!I7:I86)) -> 3 | E19: =IFERROR(D19/C19,"-") -> 1.5 | F19: =IF(ISNUMBER(E19),LOOKUP(E19,Data!$AD$2:$AD$5,Data!$AE$2:$AE$5),"") -> ممتاز Excellent
A20: =ROW()-ROW($A$16) -> 4 | B20: برامج التطوير وبناء القدرات | Capacity & Development Programs | C20: =IF('KPI Tracking'!$P$3="",SUMIFS(الأنشطة!H7:H86,الأنشطة!C7:C86,Data!$AG$4),SUMPRODUCT((الأنشطة!B7:B86<>"")*(RIGHT(الأنشطة!B7:B86,1)<=RIGHT('KPI Tracking'!$P$3,1))*(الأنشطة!C7:C86=Data!$AG$4)*الأنشطة!H7:H86)) -> 2 | D20: =IF('KPI Tracking'!$P$3="",SUMIFS(الأنشطة!I7:I86,الأنشطة!C7:C86,Data!$AG$4),SUMPRODUCT((الأنشطة!B7:B86<>"")*(RIGHT(الأنشطة!B7:B86,1)<=RIGHT('KPI Tracking'!$P$3,1))*(الأنشطة!C7:C86=Data!$AG$4)*الأنشطة!I7:I86)) -> 2 | E20: =IFERROR(D20/C20,"-") -> 1 | F20: =IF(ISNUMBER(E20),LOOKUP(E20,Data!$AD$2:$AD$5,Data!$AE$2:$AE$5),"") -> ممتاز Excellent
A21: =ROW()-ROW($A$16) -> 5 | E21: =IFERROR(D21/C21,"-") -> - | F21: =IF(ISNUMBER(E21),LOOKUP(E21,Data!$AD$2:$AD$5,Data!$AE$2:$AE$5),"")
A22: =ROW()-ROW($A$16) -> 6 | E22: =IFERROR(D22/C22,"-") -> - | F22: =IF(ISNUMBER(E22),LOOKUP(E22,Data!$AD$2:$AD$5,Data!$AE$2:$AE$5),"")
A24: الإحصاءات السنوية والمقارنة | ANNUAL STATISTICS & COMPARISON
A25: # | B25: الفئة | Category | C25: السنة السابقة | Previous Year | D25: السنة الحالية | Current Year | E25: نسبة التغير | Change % | F25: الملاحظة Note
A26: =ROW()-ROW($A$25) -> 1 | B26: عدد الطلاب/المستفيدين | Students/Beneficiaries | C26: 4000 | D26: 5000 | E26: =IFERROR((D26-C26)/C26,"-") -> 0.25
A27: =ROW()-ROW($A$25) -> 2 | B27: عدد الموظفين/الكادر | Staff | E27: =IFERROR((D27-C27)/C27,"-") -> -
A28: =ROW()-ROW($A$25) -> 3 | B28: عدد الخريجين/المشاركين الذين أكملوا البرامج| Number of Graduates/Participants Completing Programs | E28: =IFERROR((D28-C28)/C28,"-") -> -
A29: =ROW()-ROW($A$25) -> 4 | B29: عدد الشراكات/الفعاليات | Partnerships/Events | E29: =IFERROR((D29-C29)/C29,"-") -> -
A30: =ROW()-ROW($A$25) -> 5 | B30: الميزانية التشغيلية Operating Budget | E30: =IFERROR((D30-C30)/C30,"-") -> -
A31: =ROW()-ROW($A$25) -> 6 | E31: =IFERROR((D31-C31)/C31,"-") -> -
A33: أبرز الإنجازات / Key Achievements
A34: # | B34: الإنجاز Achievement | C34: المجال Area | D34: الأثر Impact | E34: كود المؤشر الداعم Supporting KPI Code | F34: الملاحظة Note
A35: =ROW()-ROW($A$34) -> 1 | B35: إطلاق برنامج سبل العيش | C35: البرامج | D35: مرتفع High | E35: ZF-S2
A36: =ROW()-ROW($A$34) -> 2
A37: =ROW()-ROW($A$34) -> 3
A38: =ROW()-ROW($A$34) -> 4
A39: =ROW()-ROW($A$34) -> 5
A40: =ROW()-ROW($A$34) -> 6
A41: =ROW()-ROW($A$34) -> 7
A42: =ROW()-ROW($A$34) -> 8
A44: التحديات الرئيسية / Key Challenges
...

Sheet Data
A1: اسم المؤسسة Institution | B1: الاختصار Abbrev. | D1: الفترة Period | F1: المنظور Perspective | H1: طبيعة القياس Measurement Nature | J1: دور المؤشر KPI Role | L1: الوحدة Unit | N1: القطبية Polarity | P1: التردد Frequency | R1: وحدات القياس العددي Number Units | T1: وحدة القياس النسبي Percentage Unit | V1: وحدة القياس النوعي Qualitative Unit | X1: تردد المؤشرات النوعية Qualitative Frequency | Z1: الأولوية Priority | AB1: مستوى الأثر Impact Level | AD1: الحد الأدنى للنسبة Min % | AE1: التقييم Rating | AG1: نوع النشاط Activity Type
A2: مؤسسة زمزم Zamzam Foundation | B2: ZF | D2: Q1 | F2: أصحاب المصلحة Stakeholder | H2: كمي نسبي Quantitative % | J2: قيادي Leading | L2: عدد Number | N2: تصاعدي Ascending | P2: ربعي - مستقل Quarterly-Independent | R2: عدد Number | T2: نسبة % Percentage | V2: مقياس ليكرت الخماسي Likert 1-5 | X2: ربعي - متوسط Quarterly-Average | Z2: عالية / High | AB2: مرتفع High | AD2: 0 | AE2: ضعيف Weak | AG2: برنامج / مشروع / نشاط Program / Project / Activity
